Workbook
Name Slicer_Dept_cleaned1: #N/A
Name Slicer_Performance_Category_calculated: #N/A

Sheet Data_preprocessing
A1: Name | B1: Age | C1: Salary | D1: Gender | E1: Department | F1: Position | G1: Joining Date | H1: Performance Score | I1: Email | J1: Phone Number | M1: Name_cleaned | N1: Age_removedtextvalues | O1: age_cleaned | P1: Salary | Q1: Salary_cleaned | R1: Gender_cleaned | S1: Dept_cleaned | T1: Position_cleaned | U1: Joining Date_cleaned | V1: Performance Score_cleaned | W1: Email_blankReplaced | X1: Email_hyphen replaced | Y1: Email_cleaned | Z1: Phone_cleaned
A2: grace | B2: 25 | C2: 50000 | D2: Male | E2: HR | F2: Manager | G2: 43195 | H2: D | I2: email@example/com | J2: nan | M2: =PROPER(TRIM(CLEAN(A2:A1001))) -> Grace | N2: 25 | O2: =IF(ISNUMBER(N2),N2,MEDIAN($N$2:$N$1001)) -> 25 | P2: 50000 | Q2: =IF(ISNUMBER(P2),P2,MEDIAN(P2:P1001)) -> 50000 | R2: =PROPER(TRIM(CLEAN(D2:D1001))) -> Male | S2: =TRIM(CLEAN(E2:E1001)) -> HR | T2: =TRIM(CLEAN(F2:F1001)) -> Manager | U2: 43195 | V2: D | W2: email@example/com | X2: =IF( OR(TRIM(W2)="",LOWER(W2)="nan"), "Email not provided", W2 ) -> email@example/com | Y2: =SUBSTITUTE(X2,"/",".") -> email@example.com | Z2: =IF(OR(TRIM(J2)="", LOWER(J2)="nan"), "Phone not provided", TRIM(J2)) -> Phone not provided
A3: david | B3: nan | C3: 65000 | D3: Female | E3: Finance | F3: Director | G3: 43881 | H3: F | I3: user@domain/com | J3: 123-456-7890 | M3: =PROPER(TRIM(CLEAN(A3:A1002))) -> David | N3: nan | O3: =IF(ISNUMBER(N3),N3,MEDIAN($N$2:$N$1001)) -> 35 | P3: 65000 | Q3: =IF(ISNUMBER(P3),P3,MEDIAN(P3:P1002)) -> 65000 | R3: =PROPER(TRIM(CLEAN(D3:D1002))) -> Female | S3: =TRIM(CLEAN(E3:E1002)) -> Finance | T3: =TRIM(CLEAN(F3:F1002)) -> Director | U3: 43881 | V3: F | W3: user@domain/com | X3: =IF( OR(TRIM(W3)="",LOWER(W3)="nan"), "Email not provided", W3 ) -> user@domain/com | Y3: =SUBSTITUTE(X3,"/",".") -> user@domain.com | Z3: =IF(OR(TRIM(J3)="", LOWER(J3)="nan"), "Phone not provided", TRIM(J3)) -> 123-456-7890
A4: hannah | B4: 35 | C4: 60000 | D4: Female | E4: Sales | F4: Director | G4: 43845 | H4: C | I4: email@example/com | J4: 098-765-4321 | M4: =PROPER(TRIM(CLEAN(A4:A1003))) -> Hannah | N4: 35 | O4: =IF(ISNUMBER(N4),N4,MEDIAN($N$2:$N$1001)) -> 35 | P4: 60000 | Q4: =IF(ISNUMBER(P4),P4,MEDIAN(P4:P1003)) -> 60000 | R4: =PROPER(TRIM(CLEAN(D4:D1003))) -> Female | S4: =TRIM(CLEAN(E4:E1003)) -> Sales | T4: =TRIM(CLEAN(F4:F1003)) -> Director | U4: 43845 | V4: C | W4: email@example/com | X4: =IF( OR(TRIM(W4)="",LOWER(W4)="nan"), "Email not provided", W4 ) -> email@example/com | Y4: =SUBSTITUTE(X4,"/",".") -> email@example.com | Z4: =IF(OR(TRIM(J4)="", LOWER(J4)="nan"), "Phone not provided", TRIM(J4)) -> 098-765-4321
A5: eve | B5: nan | C5: 50000 | D5: Female | E5: IT | F5: Manager | G5: 43195 | H5: A | I5: name@company/org | M5: =PROPER(TRIM(CLEAN(A5:A1004))) -> Eve | N5: nan | O5: =IF(ISNUMBER(N5),N5,MEDIAN($N$2:$N$1001)) -> 35 | P5: 50000 | Q5: =IF(ISNUMBER(P5),P5,MEDIAN(P5:P1004)) -> 50000 | R5: =PROPER(TRIM(CLEAN(D5:D1004))) -> Female | S5: =TRIM(CLEAN(E5:E1004)) -> IT | T5: =TRIM(CLEAN(F5:F1004)) -> Manager | U5: 43195 | V5: A | W5: name@company/org | X5: =IF( OR(TRIM(W5)="",LOWER(W5)="nan"), "Email not provided", W5 ) -> name@company/org | Y5: =SUBSTITUTE(X5,"/",".") -> name@company.org | Z5: =IF(OR(TRIM(J5)="", LOWER(J5)="nan"), "Phone not provided", TRIM(J5)) -> Phone not provided
A6: grace | B6: nan | C6: NAN | D6: Female | E6: Finance | F6: Manager | G6: 43845 | H6: F | I6: name@company/org | J6: 098-765-4321 | M6: =PROPER(TRIM(CLEAN(A6:A1005))) -> Grace | N6: nan | O6: =IF(ISNUMBER(N6),N6,MEDIAN($N$2:$N$1001)) -> 35 | P6: NAN | Q6: =IF(ISNUMBER(P6),P6,MEDIAN(P6:P1005)) -> 60000 | R6: =PROPER(TRIM(CLEAN(D6:D1005))) -> Female | S6: =TRIM(CLEAN(E6:E1005)) -> Finance | T6: =TRIM(CLEAN(F6:F1005)) -> Manager | U6: 43845 | V6: F | W6: name@company/org | X6: =IF( OR(TRIM(W6)="",LOWER(W6)="nan"), "Email not provided", W6 ) -> name@company/org | Y6: =SUBSTITUTE(X6,"/",".") -> name@company.org | Z6: =IF(OR(TRIM(J6)="", LOWER(J6)="nan"), "Phone not provided", TRIM(J6)) -> 098-765-4321
A7: jack | B7: nan | C7: 65000 | D7: Other | E7: Marketing | F7: Director | G7: 43549 | H7: F | I7: user@domain/com | J7: nan | M7: =PROPER(TRIM(CLEAN(A7:A1006))) -> Jack | N7: nan | O7: =IF(ISNUMBER(N7),N7,MEDIAN($N$2:$N$1001)) -> 35 | P7: 65000 | Q7: =IF(ISNUMBER(P7),P7,MEDIAN(P7:P1006)) -> 65000 | R7: =PROPER(TRIM(CLEAN(D7:D1006))) -> Other | S7: =TRIM(CLEAN(E7:E1006)) -> Marketing | T7: =TRIM(CLEAN(F7:F1006)) -> Director | U7: 43549 | V7: F | W7: user@domain/com | X7: =IF( OR(TRIM(W7)="",LOWER(W7)="nan"), "Email not provided", W7 ) -> user@domain/com | Y7: =SUBSTITUTE(X7,"/",".") -> user@domain.com | Z7: =IF(OR(TRIM(J7)="", LOWER(J7)="nan"), "Phone not provided", TRIM(J7)) -> Phone not provided
A8: charlie | B8: nan | C8: 50000 | D8: Male | E8: Marketing | F8: Clerk | G8: 43800 | H8: B | J8: 123-456-7890 | M8: =PROPER(TRIM(CLEAN(A8:A1007))) -> Charlie | N8: nan | O8: =IF(ISNUMBER(N8),N8,MEDIAN($N$2:$N$1001)) -> 35 | P8: 50000 | Q8: =IF(ISNUMBER(P8),P8,MEDIAN(P8:P1007)) -> 50000 | R8: =PROPER(TRIM(CLEAN(D8:D1007))) -> Male | S8: =TRIM(CLEAN(E8:E1007)) -> Marketing | T8: =TRIM(CLEAN(F8:F1007)) -> Clerk | U8: 43800 | V8: B | X8: =IF( OR(TRIM(W8)="",LOWER(W8)="nan"), "Email not provided", W8 ) -> Email not provided | Y8: =SUBSTITUTE(X8,"/",".") -> Email not provided | Z8: =IF(OR(TRIM(J8)="", LOWER(J8)="nan"), "Phone not provided", TRIM(J8)) -> 123-456-7890
A9: grace | B9: 40 | C9: 50000 | D9: Other | E9: HR | F9: Director | G9: 43549 | H9: C | M9: =PROPER(TRIM(CLEAN(A9:A1008))) -> Grace | N9: 40 | O9: =IF(ISNUMBER(N9),N9,MEDIAN($N$2:$N$1001)) -> 40 | P9: 50000 | Q9: =IF(ISNUMBER(P9),P9,MEDIAN(P9:P1008)) -> 50000 | R9: =PROPER(TRIM(CLEAN(D9:D1008))) -> Other | S9: =TRIM(CLEAN(E9:E1008)) -> HR | T9: =TRIM(CLEAN(F9:F1008)) -> Director | U9: 43549 | V9: C | X9: =IF( OR(TRIM(W9)="",LOWER(W9)="nan"), "Email not provided", W9 ) -> Email not provided | Y9: =SUBSTITUTE(X9,"/",".") -> Email not provided | Z9: =IF(OR(TRIM(J9)="", LOWER(J9)="nan"), "Phone not provided", TRIM(J9)) -> Phone not provided
A10: hannah | B10: 40 | C10: 60000 | D10: Female | E10: Marketing | F10: Manager | G10: 43845 | H10: C | I10: user@domain/com | J10: 123-456-7890 | M10: =PROPER(TRIM(CLEAN(A10:A1009))) -> Hannah | N10: 40 | O10: =IF(ISNUMBER(N10),N10,MEDIAN($N$2:$N$1001)) -> 40 | P10: 60000 | Q10: =IF(ISNUMBER(P10),P10,MEDIAN(P10:P1009)) -> 60000 | R10: =PROPER(TRIM(CLEAN(D10:D1009))) -> Female | S10: =TRIM(CLEAN(E10:E1009)) -> Marketing | T10: =TRIM(CLEAN(F10:F1009)) -> Manager | U10: 43845 | V10: C | W10: user@domain/com | X10: =IF( OR(TRIM(W10)="",LOWER(W10)="nan"), "Email not provided", W10 ) -> user@domain/com | Y10: =SUBSTITUTE(X10,"/",".") -> user@domain.com | Z10: =IF(OR(TRIM(J10)="", LOWER(J10)="nan"), "Phone not provided", TRIM(J10)) -> 123-456-7890
A11: eve | B11: 30 | C11: NAN | D11: Other | E11: Finance | F11: Assistant | G11: 43881 | H11: A | M11: =PROPER(TRIM(CLEAN(A11:A1010))) -> Eve | N11: 30 | O11: =IF(ISNUMBER(N11),N11,MEDIAN($N$2:$N$1001)) -> 30 | P11: NAN | Q11: =IF(ISNUMBER(P11),P11,MEDIAN(P11:P1010)) -> 60000 | R11: =PROPER(TRIM(CLEAN(D11:D1010))) -> Other | S11: =TRIM(CLEAN(E11:E1010)) -> Finance | T11: =TRIM(CLEAN(F11:F1010)) -> Assistant | U11: 43881 | V11: A | X11: =IF( OR(TRIM(W11)="",LOWER(W11)="nan"), "Email not provided", W11 ) -> Email not provided | Y11: =SUBSTITUTE(X11,"/",".") -> Email not provided | Z11: =IF(OR(TRIM(J11)="", LOWER(J11)="nan"), "Phone not provided", TRIM(J11)) -> Phone not provided
A12: david | B12: 25 | C12: 70000 | D12: Male | E12: Marketing | F12: Analyst | G12: 43800 | H12: B | I12: nan | J12: 123-456-7890 | M12: =PROPER(TRIM(CLEAN(A12:A1011))) -> David | N12: 25 | O12: =IF(ISNUMBER(N12),N12,MEDIAN($N$2:$N$1001)) -> 25 | P12: 70000 | Q12: =IF(ISNUMBER(P12),P12,MEDIAN(P12:P1011)) -> 70000 | R12: =PROPER(TRIM(CLEAN(D12:D1011))) -> Male | S12: =TRIM(CLEAN(E12:E1011)) -> Marketing | T12: =TRIM(CLEAN(F12:F1011)) -> Analyst | U12: 43800 | V12: B | W12: nan | X12: =IF( OR(TRIM(W12)="",LOWER(W12)="nan"), "Email not provided", W12 ) -> Email not provided | Y12: =SUBSTITUTE(X12,"/",".") -> Email not provided | Z12: =IF(OR(TRIM(J12)="", LOWER(J12)="nan"), "Phone not provided", TRIM(J12)) -> 123-456-7890
A13: hannah | B13: nan | C13: 70000 | D13: Other | E13: Finance | F13: Assistant | G13: 43549 | H13: A | J13: nan | M13: =PROPER(TRIM(CLEAN(A13:A1012))) -> Hannah | N13: nan | O13: =IF(ISNUMBER(N13),N13,MEDIAN($N$2:$N$1001)) -> 35 | P13: 70000 | Q13: =IF(ISNUMBER(P13),P13,MEDIAN(P13:P1012)) -> 70000 | R13: =PROPER(TRIM(CLEAN(D13:D1012))) -> Other | S13: =TRIM(CLEAN(E13:E1012)) -> Finance | T13: =TRIM(CLEAN(F13:F1012)) -> Assistant | U13: 43549 | V13: A | X13: =IF( OR(TRIM(W13)="",LOWER(W13)="nan"), "Email not provided", W13 ) -> Email not provided | Y13: =SUBSTITUTE(X13,"/",".") -> Email not provided | Z13: =IF(OR(TRIM(J13)="", LOWER(J13)="nan"), "Phone not provided", TRIM(J13)) -> Phone not provided
A14: hannah | B14: 30 | C14: 50000 | D14: Male | E14: IT | F14: Assistant | G14: 43195 | H14: D | M14: =PROPER(TRIM(CLEAN(A14:A1013))) -> Hannah | N14: 30 | O14: =IF(ISNUMBER(N14),N14,MEDIAN($N$2:$N$1001)) -> 30 | P14: 50000 | Q14: =IF(ISNUMBER(P14),P14,MEDIAN(P14:P1013)) -> 50000 | R14: =PROPER(TRIM(CLEAN(D14:D1013))) -> Male | S14: =TRIM(CLEAN(E14:E1013)) -> IT | T14: =TRIM(CLEAN(F14:F1013)) -> Assistant | U14: 43195 | V14: D | X14: =IF( OR(TRIM(W14)="",LOWER(W14)="nan"), "Email not provided", W14 ) -> Email not provided | Y14: =SUBSTITUTE(X14,"/",".") -> Email not provided | Z14: =IF(OR(TRIM(J14)="", LOWER(J14)="nan"), "Phone not provided", TRIM(J14)) -> Phone not provided
A15: charlie | B15: 25 | C15: 55000 | D15: Other | E15: HR | F15: Manager | G15: 43881 | H15: F | J15: 555-555-5555 | M15: =PROPER(TRIM(CLEAN(A15:A1014))) -> Charlie | N15: 25 | O15: =IF(ISNUMBER(N15),N15,MEDIAN($N$2:$N$1001)) -> 25 | P15: 55000 | Q15: =IF(ISNUMBER(P15),P15,MEDIAN(P15:P1014)) -> 55000 | R15: =PROPER(TRIM(CLEAN(D15:D1014))) -> Other | S15: =TRIM(CLEAN(E15:E1014)) -> HR | T15: =TRIM(CLEAN(F15:F1014)) -> Manager | U15: 43881 | V15: F | X15: =IF( OR(TRIM(W15)="",LOWER(W15)="nan"), "Email not provided", W15 ) -> Email not provided | Y15: =SUBSTITUTE(X15,"/",".") -> Email not provided | Z15: =IF(OR(TRIM(J15)="", LOWER(J15)="nan"), "Phone not provided", TRIM(J15)) -> 555-555-5555
A16: frank | B16: 50 | C16: NAN | D16: Male | E16: Marketing | F16: Director | G16: 43549 | H16: A | I16: nan | J16: 123-456-7890 | M16: =PROPER(TRIM(CLEAN(A16:A1015))) -> Frank | N16: 50 | O16: =IF(ISNUMBER(N16),N16,MEDIAN($N$2:$N$1001)) -> 50 | P16: NAN | Q16: =IF(ISNUMBER(P16),P16,MEDIAN(P16:P1015)) -> 60000 | R16: =PROPER(TRIM(CLEAN(D16:D1015))) -> Male | S16: =TRIM(CLEAN(E16:E1015)) -> Marketing | T16: =TRIM(CLEAN(F16:F1015)) -> Director | U16: 43549 | V16: A | W16: nan | X16: =IF( OR(TRIM(W16)="",LOWER(W16)="nan"), "Email not provided", W16 ) -> Email not provided | Y16: =SUBSTITUTE(X16,"/",".") -> Email not provided | Z16: =IF(OR(TRIM(J16)="", LOWER(J16)="nan"), "Phone not provided", TRIM(J16)) -> 123-456-7890
A17: eve | B17: 35 | C17: 65000 | D17: Male | E17: Finance | F17: Clerk | G17: 43195 | H17: F | J17: 123-456-7890 | M17: =PROPER(TRIM(CLEAN(A17:A1016))) -> Eve | N17: 35 | O17: =IF(ISNUMBER(N17),N17,MEDIAN($N$2:$N$1001)) -> 35 | P17: 65000 | Q17: =IF(ISNUMBER(P17),P17,MEDIAN(P17:P1016)) -> 65000 | R17: =PROPER(TRIM(CLEAN(D17:D1016))) -> Male | S17: =TRIM(CLEAN(E17:E1016)) -> Finance | T17: =TRIM(CLEAN(F17:F1016)) -> Clerk | U17: 43195 | V17: F | X17: =IF( OR(TRIM(W17)="",LOWER(W17)="nan"), "Email not provided", W17 ) -> Email not provided | Y17: =SUBSTITUTE(X17,"/",".") -> Email not provided | Z17: =IF(OR(TRIM(J17)="", LOWER(J17)="nan"), "Phone not provided", TRIM(J17)) -> 123-456-7890
A18: bob | B18: 40 | C18: 55000 | D18: Female | E18: Sales | F18: Assistant | G18: 43845 | H18: B | I18: nan | J18: 098-765-4321 | M18: =PROPER(TRIM(CLEAN(A18:A1017))) -> Bob | N18: 40 | O18: =IF(ISNUMBER(N18),N18,MEDIAN($N$2:$N$1001)) -> 40 | P18: 55000 | Q18: =IF(ISNUMBER(P18),P18,MEDIAN(P18:P1017)) -> 55000 | R18: =PROPER(TRIM(CLEAN(D18:D1017))) -> Female | S18: =TRIM(CLEAN(E18:E1017)) -> Sales | T18: =TRIM(CLEAN(F18:F1017)) -> Assistant | U18: 43845 | V18: B | W18: nan | X18: =IF( OR(TRIM(W18)="",LOWER(W18)="nan"), "Email not provided", W18 ) -> Email not provided | Y18: =SUBSTITUTE(X18,"/",".") -> Email not provided | Z18: =IF(OR(TRIM(J18)="", LOWER(J18)="nan"), "Phone not provided", TRIM(J18)) -> 098-765-4321
A19: hannah | B19: 50 | C19: 55000 | D19: Male | E19: HR | F19: Director | G19: 43195 | H19: D | I19: user@domain/com | M19: =PROPER(TRIM(CLEAN(A19:A1018))) -> Hannah | N19: 50 | O19: =IF(ISNUMBER(N19),N19,MEDIAN($N$2:$N$1001)) -> 50 | P19: 55000 | Q19: =IF(ISNUMBER(P19),P19,MEDIAN(P19:P1018)) -> 55000 | R19: =PROPER(TRIM(CLEAN(D19:D1018))) -> Male | S19: =TRIM(CLEAN(E19:E1018)) -> HR | T19: =TRIM(CLEAN(F19:F1018)) -> Director | U19: 43195 | V19: D | W19: user@domain/com | X19: =IF( OR(TRIM(W19)="",LOWER(W19)="nan"), "Email not provided", W19 ) -> user@domain/com | Y19: =SUBSTITUTE(X19,"/",".") -> user@domain.com | Z19: =IF(OR(TRIM(J19)="", LOWER(J19)="nan"), "Phone not provided", TRIM(J19)) -> Phone not provided
A20: frank | B20: 25 | C20: NAN | D20: Female | E20: IT | F20: Clerk | G20: 43549 | H20: B | I20: email@example/com | J20: 555-555-5555 | M20: =PROPER(TRIM(CLEAN(A20:A1019))) -> Frank | N20: 25 | O20: =IF(ISNUMBER(N20),N20,MEDIAN($N$2:$N$1001)) -> 25 | P20: NAN | Q20: =IF(ISNUMBER(P20),P20,MEDIAN(P20:P1019)) -> 60000 | R20: =PROPER(TRIM(CLEAN(D20:D1019))) -> Female | S20: =TRIM(CLEAN(E20:E1019)) -> IT | T20: =TRIM(CLEAN(F20:F1019)) -> Clerk | U20: 43549 | V20: B | W20: email@example/com | X20: =IF( OR(TRIM(W20)="",LOWER(W20)="nan"), "Email not provided", W20 ) -> email@example/com | Y20: =SUBSTITUTE(X20,"/",".") -> email@example.com | Z20: =IF(OR(TRIM(J20)="", LOWER(J20)="nan"), "Phone not provided", TRIM(J20)) -> 555-555-5555
A21: bob | B21: 50 | C21: 50000 | D21: Female | E21: Finance | F21: Assistant | G21: 43549 | H21: D | I21: user@domain/com | J21: nan | M21: =PROPER(TRIM(CLEAN(A21:A1020))) -> Bob | N21: 50 | O21: =IF(ISNUMBER(N21),N21,MEDIAN($N$2:$N$1001)) -> 50 | P21: 50000 | Q21: =IF(ISNUMBER(P21),P21,MEDIAN(P21:P1020)) -> 50000 | R21: =PROPER(TRIM(CLEAN(D21:D1020))) -> Female | S21: =TRIM(CLEAN(E21:E1020)) -> Finance | T21: =TRIM(CLEAN(F21:F1020)) -> Assistant | U21: 43549 | V21: D | W21: user@domain/com | X21: =IF( OR(TRIM(W21)="",LOWER(W21)="nan"), "Email not provided", W21 ) -> user@domain/com | Y21: =SUBSTITUTE(X21,"/",".") -> user@domain.com | Z21: =IF(OR(TRIM(J21)="", LOWER(J21)="nan"), "Phone not provided", TRIM(J21)) -> Phone not provided
A22: eve | B22: 35 | C22: 50000 | D22: Female | E22: IT | F22: Clerk | G22: 43845 | H22: D | I22: email@example/com | J22: 098-765-4321 | M22: =PROPER(TRIM(CLEAN(A22:A1021))) -> Eve | N22: 35 | O22: =IF(ISNUMBER(N22),N22,MEDIAN($N$2:$N$1001)) -> 35 | P22: 50000 | Q22: =IF(ISNUMBER(P22),P22,MEDIAN(P22:P1021)) -> 50000 | R22: =PROPER(TRIM(CLEAN(D22:D1021))) -> Female | S22: =TRIM(CLEAN(E22:E1021)) -> IT | T22: =TRIM(CLEAN(F22:F1021)) -> Clerk | U22: 43845 | V22: D | W22: email@example/com | X22: =IF( OR(TRIM(W22)="",LOWER(W22)="nan"), "Email not provided", W22 ) -> email@example/com | Y22: =SUBSTITUTE(X22,"/",".") -> email@example.com | Z22: =IF(OR(TRIM(J22)="", LOWER(J22)="nan"), "Phone not provided", TRIM(J22)) -> 098-765-4321
A23: alice | B23: 25 | C23: 50000 | D23: Other | E23: IT | F23: Director | G23: 43195 | H23: F | I23: user@domain/com | J23: 555-555-5555 | M23: =PROPER(TRIM(CLEAN(A23:A1022))) -> Alice | N23: 25 | O23: =IF(ISNUMBER(N23),N23,MEDIAN($N$2:$N$1001)) -> 25 | P23: 50000 | Q23: =IF(ISNUMBER(P23),P23,MEDIAN(P23:P1022)) -> 50000 | R23: =PROPER(TRIM(CLEAN(D23:D1022))) -> Other | S23: =TRIM(CLEAN(E23:E1022)) -> IT | T23: =TRIM(CLEAN(F23:F1022)) -> Director | U23: 43195 | V23: F | W23: user@domain/com | X23: =IF( OR(TRIM(W23)="",LOWER(W23)="nan"), "Email not provided", W23 ) -> user@domain/com | Y23: =SUBSTITUTE(X23,"/",".") -> user@domain.com | Z23: =IF(OR(TRIM(J23)="", LOWER(J23)="nan"), "Phone not provided", TRIM(J23)) -> 555-555-5555
A24: jack | B24: 50 | C24: 50000 | D24: Other | E24: Marketing | F24: Analyst | G24: 43195 | H24: B | I24: email@example/com | M24: =PROPER(TRIM(CLEAN(A24:A1023))) -> Jack | N24: 50 | O24: =IF(ISNUMBER(N24),N24,MEDIAN($N$2:$N$1001)) -> 50 | P24: 50000 | Q24: =IF(ISNUMBER(P24),P24,MEDIAN(P24:P1023)) -> 50000 | R24: =PROPER(TRIM(CLEAN(D24:D1023))) -> Other | S24: =TRIM(CLEAN(E24:E1023)) -> Marketing | T24: =TRIM(CLEAN(F24:F1023)) -> Analyst | U24: 43195 | V24: B | W24: email@example/com | X24: =IF( OR(TRIM(W24)="",LOWER(W24)="nan"), "Email not provided", W24 ) -> email@example/com | Y24: =SUBSTITUTE(X24,"/",".") -> email@example.com | Z24: =IF(OR(TRIM(J24)="", LOWER(J24)="nan"), "Phone not provided", TRIM(J24)) -> Phone not provided
A25: frank | B25: 40 | C25: 70000 | D25: Other | E25: Marketing | F25: Director | G25: 43845 | H25: B | I25: email@example/com | J25: 555-555-5555 | M25: =PROPER(TRIM(CLEAN(A25:A1024))) -> Frank | N25: 40 | O25: =IF(ISNUMBER(N25),N25,MEDIAN($N$2:$N$1001)) -> 40 | P25: 70000 | Q25: =IF(ISNUMBER(P25),P25,MEDIAN(P25:P1024)) -> 70000 | R25: =PROPER(TRIM(CLEAN(D25:D1024))) -> Other | S25: =TRIM(CLEAN(E25:E1024)) -> Marketing | T25: =TRIM(CLEAN(F25:F1024)) -> Director | U25: 43845 | V25: B | W25: email@example/com | X25: =IF( OR(TRIM(W25)="",LOWER(W25)="nan"), "Email not provided", W25 ) -> email@example/com | Y25: =SUBSTITUTE(X25,"/",".") -> email@example.com | Z25: =IF(OR(TRIM(J25)="", LOWER(J25)="nan"), "Phone not provided", TRIM(J25)) -> 555-555-5555
A26: ivy | B26: 40 | C26: 50000 | D26: Other | E26: Finance | F26: Manager | G26: 43195 | H26: A | I26: name@company/org | J26: 123-456-7890 | M26: =PROPER(TRIM(CLEAN(A26:A1025))) -> Ivy | N26: 40 | O26: =IF(ISNUMBER(N26),N26,MEDIAN($N$2:$N$1001)) -> 40 | P26: 50000 | Q26: =IF(ISNUMBER(P26),P26,MEDIAN(P26:P1025)) -> 50000 | R26: =PROPER(TRIM(CLEAN(D26:D1025))) -> Other | S26: =TRIM(CLEAN(E26:E1025)) -> Finance | T26: =TRIM(CLEAN(F26:F1025)) -> Manager | U26: 43195 | V26: A | W26: name@company/org | X26: =IF( OR(TRIM(W26)="",LOWER(W26)="nan"), "Email not provided", W26 ) -> name@company/org | Y26: =SUBSTITUTE(X26,"/",".") -> name@company.org | Z26: =IF(OR(TRIM(J26)="", LOWER(J26)="nan"), "Phone not provided", TRIM(J26)) -> 123-456-7890
A27: alice | B27: 30 | C27: 70000 | D27: Male | E27: Sales | F27: Clerk | G27: 43845 | H27: B | I27: email@example/com | J27: 123-456-7890 | M27: =PROPER(TRIM(CLEAN(A27:A1026))) -> Alice | N27: 30 | O27: =IF(ISNUMBER(N27),N27,MEDIAN($N$2:$N$1001)) -> 30 | P27: 70000 | Q27: =IF(ISNUMBER(P27),P27,MEDIAN(P27:P1026)) -> 70000 | R27: =PROPER(TRIM(CLEAN(D27:D1026))) -> Male | S27: =TRIM(CLEAN(E27:E1026)) -> Sales | T27: =TRIM(CLEAN(F27:F1026)) -> Clerk | U27: 43845 | V27: B | W27: email@example/com | X27: =IF( OR(TRIM(W27)="",LOWER(W27)="nan"), "Email not provided", W27 ) -> email@example/com | Y27: =SUBSTITUTE(X27,"/",".") -> email@example.com | Z27: =IF(OR(TRIM(J27)="", LOWER(J27)="nan"), "Phone not provided", TRIM(J27)) -> 123-456-7890
A28: jack | B28: 50 | C28: 70000 | D28: Male | E28: Finance | F28: Analyst | G28: 43881 | H28: A | I28: email@example/com | J28: 098-765-4321 | M28: =PROPER(TRIM(CLEAN(A28:A1027))) -> Jack | N28: 50 | O28: =IF(ISNUMBER(N28),N28,MEDIAN($N$2:$N$1001)) -> 50 | P28: 70000 | Q28: =IF(ISNUMBER(P28),P28,MEDIAN(P28:P1027)) -> 70000 | R28: =PROPER(TRIM(CLEAN(D28:D1027))) -> Male | S28: =TRIM(CLEAN(E28:E1027)) -> Finance | T28: =TRIM(CLEAN(F28:F1027)) -> Analyst | U28: 43881 | V28: A | W28: email@example/com | X28: =IF( OR(TRIM(W28)="",LOWER(W28)="nan"), "Email not provided", W28 ) -> email@example/com | Y28: =SUBSTITUTE(X28,"/",".") -> email@example.com | Z28: =IF(OR(TRIM(J28)="", LOWER(J28)="nan"), "Phone not provided", TRIM(J28)) -> 098-765-4321
A29: charlie | B29: nan | C29: 50000 | D29: Other | E29: Sales | F29: Clerk | G29: 43549 | H29: C | I29: name@company/org | M29: =PROPER(TRIM(CLEAN(A29:A1028))) -> Charlie | N29: nan | O29: =IF(ISNUMBER(N29),N29,MEDIAN($N$2:$N$1001)) -> 35 | P29: 50000 | Q29: =IF(ISNUMBER(P29),P29,MEDIAN(P29:P1028)) -> 50000 | R29: =PROPER(TRIM(CLEAN(D29:D1028))) -> Other | S29: =TRIM(CLEAN(E29:E1028)) -> Sales | T29: =TRIM(CLEAN(F29:F1028)) -> Clerk | U29: 43549 | V29: C | W29: name@company/org | X29: =IF( OR(TRIM(W29)="",LOWER(W29)="nan"), "Email not provided", W29 ) -> name@company/org | Y29: =SUBSTITUTE(X29,"/",".") -> name@company.org | Z29: =IF(OR(TRIM(J29)="", LOWER(J29)="nan"), "Phone not provided", TRIM(J29)) -> Phone not provided
A30: grace | B30: 50 | C30: 60000 | D30: Male | E30: IT | F30: Clerk | G30: 43881 | H30: C | M30: =PROPER(TRIM(CLEAN(A30:A1029))) -> Grace | N30: 50 | O30: =IF(ISNUMBER(N30),N30,MEDIAN($N$2:$N$1001)) -> 50 | P30: 60000 | Q30: =IF(ISNUMBER(P30),P30,MEDIAN(P30:P1029)) -> 60000 | R30: =PROPER(TRIM(CLEAN(D30:D1029))) -> Male | S30: =TRIM(CLEAN(E30:E1029)) -> IT | T30: =TRIM(CLEAN(F30:F1029)) -> Clerk | U30: 43881 | V30: C | X30: =IF( OR(TRIM(W30)="",LOWER(W30)="nan"), "Email not provided", W30 ) -> Email not provided | Y30: =SUBSTITUTE(X30,"/",".") -> Email not provided | Z30: =IF(OR(TRIM(J30)="", LOWER(J30)="nan"), "Phone not provided", TRIM(J30)) -> Phone not provided
A31: david | B31: 25 | C31: 65000 | D31: Male | E31: HR | F31: Assistant | G31: 43800 | H31: C | J31: 555-555-5555 | M31: =PROPER(TRIM(CLEAN(A31:A1030))) -> David | N31: 25 | O31: =IF(ISNUMBER(N31),N31,MEDIAN($N$2:$N$1001)) -> 25 | P31: 65000 | Q31: =IF(ISNUMBER(P31),P31,MEDIAN(P31:P1030)) -> 65000 | R31: =PROPER(TRIM(CLEAN(D31:D1030))) -> Male | S31: =TRIM(CLEAN(E31:E1030)) -> HR | T31: =TRIM(CLEAN(F31:F1030)) -> Assistant | U31: 43800 | V31: C | X31: =IF( OR(TRIM(W31)="",LOWER(W31)="nan"), "Email not provided", W31 ) -> Email not provided | Y31: =SUBSTITUTE(X31,"/",".") -> Email not provided | Z31: =IF(OR(TRIM(J31)="", LOWER(J31)="nan"), "Phone not provided", TRIM(J31)) -> 555-555-5555
A32: ivy | B32: 25 | C32: 55000 | D32: Female | E32: Finance | F32: Manager | G32: 43800 | H32: B | I32: name@company/org | J32: 098-765-4321 | M32: =PROPER(TRIM(CLEAN(A32:A1031))) -> Ivy | N32: 25 | O32: =IF(ISNUMBER(N32),N32,MEDIAN($N$2:$N$1001)) -> 25 | P32: 55000 | Q32: =IF(ISNUMBER(P32),P32,MEDIAN(P32:P1031)) -> 55000 | R32: =PROPER(TRIM(CLEAN(D32:D1031))) -> Female | S32: =TRIM(CLEAN(E32:E1031)) -> Finance | T32: =TRIM(CLEAN(F32:F1031)) -> Manager | U32: 43800 | V32: B | W32: name@company/org | X32: =IF( OR(TRIM(W32)="",LOWER(W32)="nan"), "Email not provided", W32 ) -> name@company/org | Y32: =SUBSTITUTE(X32,"/",".") -> name@company.org | Z32: =IF(OR(TRIM(J32)="", LOWER(J32)="nan"), "Phone not provided", TRIM(J32)) -> 098-765-4321
A33: charlie | B33: 50 | C33: 70000 | D33: Female | E33: Finance | F33: Clerk | G33: 43800 | H33: B | I33: nan | M33: =PROPER(TRIM(CLEAN(A33:A1032))) -> Charlie | N33: 50 | O33: =IF(ISNUMBER(N33),N33,MEDIAN($N$2:$N$1001)) -> 50 | P33: 70000 | Q33: =IF(ISNUMBER(P33),P33,MEDIAN(P33:P1032)) -> 70000 | R33: =PROPER(TRIM(CLEAN(D33:D1032))) -> Female | S33: =TRIM(CLEAN(E33:E1032)) -> Finance | T33: =TRIM(CLEAN(F33:F1032)) -> Clerk | U33: 43800 | V33: B | W33: nan | X33: =IF( OR(TRIM(W33)="",LOWER(W33)="nan"), "Email not provided", W33 ) -> Email not provided | Y33: =SUBSTITUTE(X33,"/",".") -> Email not provided | Z33: =IF(OR(TRIM(J33)="", LOWER(J33)="nan"), "Phone not provided", TRIM(J33)) -> Phone not provided
A34: eve | B34: 35 | C34: NAN | D34: Female | E34: Sales | F34: Director | G34: 43845 | H34: A | I34: email@example/com | J34: 123-456-7890 | M34: =PROPER(TRIM(CLEAN(A34:A1033))) -> Eve | N34: 35 | O34: =IF(ISNUMBER(N34),N34,MEDIAN($N$2:$N$1001)) -> 35 | P34: NAN | Q34: =IF(ISNUMBER(P34),P34,MEDIAN(P34:P1033)) -> 60000 | R34: =PROPER(TRIM(CLEAN(D34:D1033))) -> Female | S34: =TRIM(CLEAN(E34:E1033)) -> Sales | T34: =TRIM(CLEAN(F34:F1033)) -> Director | U34: 43845 | V34: A | W34: email@example/com | X34: =IF( OR(TRIM(W34)="",LOWER(W34)="nan"), "Email not provided", W34 ) -> email@example/com | Y34: =SUBSTITUTE(X34,"/",".") -> email@example.com | Z34: =IF(OR(TRIM(J34)="", LOWER(J34)="nan"), "Phone not provided", TRIM(J34)) -> 123-456-7890
A35: charlie | B35: 40 | C35: NAN | D35: Female | E35: IT | F35: Director | G35: 43195 | H35: D | I35: email@example/com | J35: 555-555-5555 | M35: =PROPER(TRIM(CLEAN(A35:A1034))) -> Charlie | N35: 40 | O35: =IF(ISNUMBER(N35),N35,MEDIAN($N$2:$N$1001)) -> 40 | P35: NAN | Q35: =IF(ISNUMBER(P35),P35,MEDIAN(P35:P1034)) -> 60000 | R35: =PROPER(TRIM(CLEAN(D35:D1034))) -> Female | S35: =TRIM(CLEAN(E35:E1034)) -> IT | T35: =TRIM(CLEAN(F35:F1034)) -> Director | U35: 43195 | V35: D | W35: email@example/com | X35: =IF( OR(TRIM(W35)="",LOWER(W35)="nan"), "Email not provided", W35 ) -> email@example/com | Y35: =SUBSTITUTE(X35,"/",".") -> email@example.com | Z35: =IF(OR(TRIM(J35)="", LOWER(J35)="nan"), "Phone not provided", TRIM(J35)) -> 555-555-5555
A36: grace | B36: 25 | C36: 65000 | D36: Male | E36: IT | F36: Assistant | G36: 43881 | H36: A | I36: name@company/org | J36: nan | M36: =PROPER(TRIM(CLEAN(A36:A1035))) -> Grace | N36: 25 | O36: =IF(ISNUMBER(N36),N36,MEDIAN($N$2:$N$1001)) -> 25 | P36: 65000 | Q36: =IF(ISNUMBER(P36),P36,MEDIAN(P36:P1035)) -> 65000 | R36: =PROPER(TRIM(CLEAN(D36:D1035))) -> Male | S36: =TRIM(CLEAN(E36:E1035)) -> IT | T36: =TRIM(CLEAN(F36:F1035)) -> Assistant | U36: 43881 | V36: A | W36: name@company/org | X36: =IF( OR(TRIM(W36)="",LOWER(W36)="nan"), "Email not provided", W36 ) -> name@company/org | Y36: =SUBSTITUTE(X36,"/",".") -> name@company.org | Z36: =IF(OR(TRIM(J36)="", LOWER(J36)="nan"), "Phone not provided", TRIM(J36)) -> Phone not provided
A37: eve | B37: 40 | C37: NAN | D37: Other | E37: Sales | F37: Manager | G37: 43881 | H37: C | I37: name@company/org | J37: 123-456-7890 | M37: =PROPER(TRIM(CLEAN(A37:A1036))) -> Eve | N37: 40 | O37: =IF(ISNUMBER(N37),N37,MEDIAN($N$2:$N$1001)) -> 40 | P37: NAN | Q37: =IF(ISNUMBER(P37),P37,MEDIAN(P37:P1036)) -> 60000 | R37: =PROPER(TRIM(CLEAN(D37:D1036))) -> Other | S37: =TRIM(CLEAN(E37:E1036)) -> Sales | T37: =TRIM(CLEAN(F37:F1036)) -> Manager | U37: 43881 | V37: C | W37: name@company/org | X37: =IF( OR(TRIM(W37)="",LOWER(W37)="nan"), "Email not provided", W37 ) -> name@company/org | Y37: =SUBSTITUTE(X37,"/",".") -> name@company.org | Z37: =IF(OR(TRIM(J37)="", LOWER(J37)="nan"), "Phone not provided", TRIM(J37)) -> 123-456-7890
A38: ivy | B38: 25 | C38: 60000 | D38: Male | E38: IT | F38: Manager | G38: 43881 | H38: A | I38: nan | J38: 098-765-4321 | M38: =PROPER(TRIM(CLEAN(A38:A1037))) -> Ivy | N38: 25 | O38: =IF(ISNUMBER(N38),N38,MEDIAN($N$2:$N$1001)) -> 25 | P38: 60000 | Q38: =IF(ISNUMBER(P38),P38,MEDIAN(P38:P1037)) -> 60000 | R38: =PROPER(TRIM(CLEAN(D38:D1037))) -> Male | S38: =TRIM(CLEAN(E38:E1037)) -> IT | T38: =TRIM(CLEAN(F38:F1037)) -> Manager | U38: 43881 | V38: A | W38: nan | X38: =IF( OR(TRIM(W38)="",LOWER(W38)="nan"), "Email not provided", W38 ) -> Email not provided | Y38: =SUBSTITUTE(X38,"/",".") -> Email not provided | Z38: =IF(OR(TRIM(J38)="", LOWER(J38)="nan"), "Phone not provided", TRIM(J38)) -> 098-765-4321
A39: grace | B39: 30 | C39: NAN | D39: Male | E39: Marketing | F39: Director | G39: 43881 | H39: D | M39: =PROPER(TRIM(CLEAN(A39:A1038))) -> Grace | N39: 30 | O39: =IF(ISNUMBER(N39),N39,MEDIAN($N$2:$N$1001)) -> 30 | P39: NAN | Q39: =IF(ISNUMBER(P39),P39,MEDIAN(P39:P1038)) -> 60000 | R39: =PROPER(TRIM(CLEAN(D39:D1038))) -> Male | S39: =TRIM(CLEAN(E39:E1038)) -> Marketing | T39: =TRIM(CLEAN(F39:F1038)) -> Director | U39: 43881 | V39: D | X39: =IF( OR(TRIM(W39)="",LOWER(W39)="nan"), "Email not provided", W39 ) -> Email not provided | Y39: =SUBSTITUTE(X39,"/",".") -> Email not provided | Z39: =IF(OR(TRIM(J39)="", LOWER(J39)="nan"), "Phone not provided", TRIM(J39)) -> Phone not provided
A40: bob | B40: nan | C40: 55000 | D40: Male | E40: HR | F40: Analyst | G40: 43800 | H40: B | I40: user@domain/com | J40: 123-456-7890 | M40: =PROPER(TRIM(CLEAN(A40:A1039))) -> Bob | N40: nan | O40: =IF(ISNUMBER(N40),N40,MEDIAN($N$2:$N$1001)) -> 35 | P40: 55000 | Q40: =IF(ISNUMBER(P40),P40,MEDIAN(P40:P1039)) -> 55000 | R40: =PROPER(TRIM(CLEAN(D40:D1039))) -> Male | S40: =TRIM(CLEAN(E40:E1039)) -> HR | T40: =TRIM(CLEAN(F40:F1039)) -> Analyst | U40: 43800 | V40: B | W40: user@domain/com | X40: =IF( OR(TRIM(W40)="",LOWER(W40)="nan"), "Email not provided", W40 ) -> user@domain/com | Y40: =SUBSTITUTE(X40,"/",".") -> user@domain.com | Z40: =IF(OR(TRIM(J40)="", LOWER(J40)="nan"), "Phone not provided", TRIM(J40)) -> 123-456-7890
...

Sheet Cleaned_Dataset
A1: Name_cleaned | B1: age_cleaned | C1: Salary_cleaned | D1: Gender_cleaned | E1: Dept_cleaned | F1: Position_cleaned | G1: Joining Date_cleaned | H1: Performance Score_cleaned | I1: Email_cleaned | J1: Phone_cleaned | K1: Experience_Years(Calculated) | L1: Salary_Band(calculated) | M1: Performance_Category(calculated)
A2: =Data_preprocessing!M2 -> Grace | B2: =Data_preprocessing!O2 -> 25 | C2: =Data_preprocessing!Q2 -> 50000 | D2: =Data_preprocessing!R2 -> Male | E2: =Data_preprocessing!S2 -> HR | F2: =Data_preprocessing!T2 -> Manager | G2: =Data_preprocessing!U2 -> 43195 | H2: =Data_preprocessing!V2 -> D | I2: =Data_preprocessing!Y2 -> email@example.com | J2: =Data_preprocessing!Z2 -> Phone not provided | K2: =DATEDIF(G2,TODAY(),"Y") -> 7 | L2: =IF(C2<60000,"Low",IF(C2<65000,"Medium","High")) -> Low | M2: =IF(H2="A","Excellent",IF(H2="B","Good",IF(H2="C","Average",IF(H2="D","Below Average","Poor")))) -> Below Average
A3: =Data_preprocessing!M3 -> David | B3: =Data_preprocessing!O3 -> 35 | C3: =Data_preprocessing!Q3 -> 65000 | D3: =Data_preprocessing!R3 -> Female | E3: =Data_preprocessing!S3 -> Finance | F3: =Data_preprocessing!T3 -> Director | G3: =Data_preprocessing!U3 -> 43881 | H3: =Data_preprocessing!V3 -> F | I3: =Data_preprocessing!Y3 -> user@domain.com | J3: =Data_preprocessing!Z3 -> 123-456-7890 | K3: =DATEDIF(G3,TODAY(),"Y") -> 5 | L3: =IF(C3<60000,"Low",IF(C3<65000,"Medium","High")) -> High | M3: =IF(H3="A","Excellent",IF(H3="B","Good",IF(H3="C","Average",IF(H3="D","Below Average","Poor")))) -> Poor
A4: =Data_preprocessing!M4 -> Hannah | B4: =Data_preprocessing!O4 -> 35 | C4: =Data_preprocessing!Q4 -> 60000 | D4: =Data_preprocessing!R4 -> Female | E4: =Data_preprocessing!S4 -> Sales | F4: =Data_preprocessing!T4 -> Director | G4: =Data_preprocessing!U4 -> 43845 | H4: =Data_preprocessing!V4 -> C | I4: =Data_preprocessing!Y4 -> email@example.com | J4: =Data_preprocessing!Z4 -> 098-765-4321 | K4: =DATEDIF(G4,TODAY(),"Y") -> 6 | L4: =IF(C4<60000,"Low",IF(C4<65000,"Medium","High")) -> Medium | M4: =IF(H4="A","Excellent",IF(H4="B","Good",IF(H4="C","Average",IF(H4="D","Below Average","Poor")))) -> Average
A5: =Data_preprocessing!M5 -> Eve | B5: =Data_preprocessing!O5 -> 35 | C5: =Data_preprocessing!Q5 -> 50000 | D5: =Data_preprocessing!R5 -> Female | E5: =Data_preprocessing!S5 -> IT | F5: =Data_preprocessing!T5 -> Manager | G5: =Data_preprocessing!U5 -> 43195 | H5: =Data_preprocessing!V5 -> A | I5: =Data_preprocessing!Y5 -> name@company.org | J5: =Data_preprocessing!Z5 -> Phone not provided | K5: =DATEDIF(G5,TODAY(),"Y") -> 7 | L5: =IF(C5<60000,"Low",IF(C5<65000,"Medium","High")) -> Low | M5: =IF(H5="A","Excellent",IF(H5="B","Good",IF(H5="C","Average",IF(H5="D","Below Average","Poor")))) -> Excellent
A6: =Data_preprocessing!M6 -> Grace | B6: =Data_preprocessing!O6 -> 35 | C6: =Data_preprocessing!Q6 -> 60000 | D6: =Data_preprocessing!R6 -> Female | E6: =Data_preprocessing!S6 -> Finance | F6: =Data_preprocessing!T6 -> Manager | G6: =Data_preprocessing!U6 -> 43845 | H6: =Data_preprocessing!V6 -> F | I6: =Data_preprocessing!Y6 -> name@company.org | J6: =Data_preprocessing!Z6 -> 098-765-4321 | K6: =DATEDIF(G6,TODAY(),"Y") -> 6 | L6: =IF(C6<60000,"Low",IF(C6<65000,"Medium","High")) -> Medium | M6: =IF(H6="A","Excellent",IF(H6="B","Good",IF(H6="C","Average",IF(H6="D","Below Average","Poor")))) -> Poor
A7: =Data_preprocessing!M7 -> Jack | B7: =Data_preprocessing!O7 -> 35 | C7: =Data_preprocessing!Q7 -> 65000 | D7: =Data_preprocessing!R7 -> Other | E7: =Data_preprocessing!S7 -> Marketing | F7: =Data_preprocessing!T7 -> Director | G7: =Data_preprocessing!U7 -> 43549 | H7: =Data_preprocessing!V7 -> F | I7: =Data_preprocessing!Y7 -> user@domain.com | J7: =Data_preprocessing!Z7 -> Phone not provided | K7: =DATEDIF(G7,TODAY(),"Y") -> 6 | L7: =IF(C7<60000,"Low",IF(C7<65000,"Medium","High")) -> High | M7: =IF(H7="A","Excellent",IF(H7="B","Good",IF(H7="C","Average",IF(H7="D","Below Average","Poor")))) -> Poor
A8: =Data_preprocessing!M8 -> Charlie | B8: =Data_preprocessing!O8 -> 35 | C8: =Data_preprocessing!Q8 -> 50000 | D8: =Data_preprocessing!R8 -> Male | E8: =Data_preprocessing!S8 -> Marketing | F8: =Data_preprocessing!T8 -> Clerk | G8: =Data_preprocessing!U8 -> 43800 | H8: =Data_preprocessing!V8 -> B | I8: =Data_preprocessing!Y8 -> Email not provided | J8: =Data_preprocessing!Z8 -> 123-456-7890 | K8: =DATEDIF(G8,TODAY(),"Y") -> 6 | L8: =IF(C8<60000,"Low",IF(C8<65000,"Medium","High")) -> Low | M8: =IF(H8="A","Excellent",IF(H8="B","Good",IF(H8="C","Average",IF(H8="D","Below Average","Poor")))) -> Good
A9: =Data_preprocessing!M9 -> Grace | B9: =Data_preprocessing!O9 -> 40 | C9: =Data_preprocessing!Q9 -> 50000 | D9: =Data_preprocessing!R9 -> Other | E9: =Data_preprocessing!S9 -> HR | F9: =Data_preprocessing!T9 -> Director | G9: =Data_preprocessing!U9 -> 43549 | H9: =Data_preprocessing!V9 -> C | I9: =Data_preprocessing!Y9 -> Email not provided | J9: =Data_preprocessing!Z9 -> Phone not provided | K9: =DATEDIF(G9,TODAY(),"Y") -> 6 | L9: =IF(C9<60000,"Low",IF(C9<65000,"Medium","High")) -> Low | M9: =IF(H9="A","Excellent",IF(H9="B","Good",IF(H9="C","Average",IF(H9="D","Below Average","Poor")))) -> Average
A10: =Data_preprocessing!M10 -> Hannah | B10: =Data_preprocessing!O10 -> 40 | C10: =Data_preprocessing!Q10 -> 60000 | D10: =Data_preprocessing!R10 -> Female | E10: =Data_preprocessing!S10 -> Marketing | F10: =Data_preprocessing!T10 -> Manager | G10: =Data_preprocessing!U10 -> 43845 | H10: =Data_preprocessing!V10 -> C | I10: =Data_preprocessing!Y10 -> user@domain.com | J10: =Data_preprocessing!Z10 -> 123-456-7890 | K10: =DATEDIF(G10,TODAY(),"Y") -> 6 | L10: =IF(C10<60000,"Low",IF(C10<65000,"Medium","High")) -> Medium | M10: =IF(H10="A","Excellent",IF(H10="B","Good",IF(H10="C","Average",IF(H10="D","Below Average","Poor")))) -> Average
A11: =Data_preprocessing!M11 -> Eve | B11: =Data_preprocessing!O11 -> 30 | C11: =Data_preprocessing!Q11 -> 60000 | D11: =Data_preprocessing!R11 -> Other | E11: =Data_preprocessing!S11 -> Finance | F11: =Data_preprocessing!T11 -> Assistant | G11: =Data_preprocessing!U11 -> 43881 | H11: =Data_preprocessing!V11 -> A | I11: =Data_preprocessing!Y11 -> Email not provided | J11: =Data_preprocessing!Z11 -> Phone not provided | K11: =DATEDIF(G11,TODAY(),"Y") -> 5 | L11: =IF(C11<60000,"Low",IF(C11<65000,"Medium","High")) -> Medium | M11: =IF(H11="A","Excellent",IF(H11="B","Good",IF(H11="C","Average",IF(H11="D","Below Average","Poor")))) -> Excellent
A12: =Data_preprocessing!M12 -> David | B12: =Data_preprocessing!O12 -> 25 | C12: =Data_preprocessing!Q12 -> 70000 | D12: =Data_preprocessing!R12 -> Male | E12: =Data_preprocessing!S12 -> Marketing | F12: =Data_preprocessing!T12 -> Analyst | G12: =Data_preprocessing!U12 -> 43800 | H12: =Data_preprocessing!V12 -> B | I12: =Data_preprocessing!Y12 -> Email not provided | J12: =Data_preprocessing!Z12 -> 123-456-7890 | K12: =DATEDIF(G12,TODAY(),"Y") -> 6 | L12: =IF(C12<60000,"Low",IF(C12<65000,"Medium","High")) -> High | M12: =IF(H12="A","Excellent",IF(H12="B","Good",IF(H12="C","Average",IF(H12="D","Below Average","Poor")))) -> Good
A13: =Data_preprocessing!M13 -> Hannah | B13: =Data_preprocessing!O13 -> 35 | C13: =Data_preprocessing!Q13 -> 70000 | D13: =Data_preprocessing!R13 -> Other | E13: =Data_preprocessing!S13 -> Finance | F13: =Data_preprocessing!T13 -> Assistant | G13: =Data_preprocessing!U13 -> 43549 | H13: =Data_preprocessing!V13 -> A | I13: =Data_preprocessing!Y13 -> Email not provided | J13: =Data_preprocessing!Z13 -> Phone not provided | K13: =DATEDIF(G13,TODAY(),"Y") -> 6 | L13: =IF(C13<60000,"Low",IF(C13<65000,"Medium","High")) -> High | M13: =IF(H13="A","Excellent",IF(H13="B","Good",IF(H13="C","Average",IF(H13="D","Below Average","Poor")))) -> Excellent
... A1001: =Data_preprocessing!M1001 -> Ivy | B1001: =Data_preprocessing!O1001 -> 30 | C1001: =Data_preprocessing!Q1001 -> 60000 | D1001: =Data_preprocessing!R1001 -> Male | E1001: =Data_preprocessing!S1001 -> Finance | F1001: =Data_preprocessing!T1001 -> Manager | G1001: =Data_preprocessing!U1001 -> 43881 | H1001: =Data_preprocessing!V1001 -> C | I1001: =Data_preprocessing!Y1001 -> user@domain.com | J1001: =Data_preprocessing!Z1001 -> 123-456-7890 | K1001: =DATEDIF(G1001,TODAY(),"Y") -> 5 | L1001: =IF(C1001<60000,"Low",IF(C1001<65000,"Medium","High")) -> Medium | M1001: =IF(H1001="A","Excellent",IF(H1001="B","Good",IF(H1001="C","Average",IF(H1001="D","Below Average","Poor")))) -> Average

Sheet Pivot tables
A2: Gender Distribution by Department | G2: Average Salary by Department | J2: Performance Category by department
A3: Count of Name_cleaned | B3: Column Labels | G3: Row Labels | H3: Average of Salary_cleaned | J3: Count of Name_cleaned | K3: Column Labels
A4: Row Labels | B4: Female | C4: Male | D4: Other | E4: Grand Total | G4: Finance | H4: 59977.064 | J4: Row Labels | K4: Average | L4: Below Average | M4: Excellent | N4: Good | O4: Poor | P4: Grand Total
A5: Finance | B5: 60 | C5: 74 | D5: 84 | E5: 218 | G5: HR | H5: 60225 | J5: Finance | K5: 37 | L5: 44 | M5: 40 | N5: 49 | O5: 48 | P5: 218
A6: HR | B6: 64 | C6: 74 | D6: 62 | E6: 200 | G6: IT | H6: 59792.746 | J6: HR | K6: 48 | L6: 38 | M6: 33 | N6: 40 | O6: 41 | P6: 200
A7: IT | B7: 57 | C7: 73 | D7: 63 | E7: 193 | G7: Marketing | H7: 60053.476 | J7: IT | K7: 40 | L7: 34 | M7: 40 | N7: 47 | O7: 32 | P7: 193
A8: Marketing | B8: 61 | C8: 66 | D8: 60 | E8: 187 | G8: Sales | H8: 60841.584 | J8: Marketing | K8: 35 | L8: 35 | M8: 41 | N8: 46 | O8: 30 | P8: 187
A9: Sales | B9: 71 | C9: 68 | D9: 63 | E9: 202 | G9: Grand Total | H9: 60180 | J9: Sales | K9: 32 | L9: 39 | M9: 38 | N9: 43 | O9: 50 | P9: 202
A10: Grand Total | B10: 313 | C10: 355 | D10: 332 | E10: 1000 | J10: Grand Total | K10: 192 | L10: 190 | M10: 192 | N10: 225 | O10: 201 | P10: 1000
